[2023-11-08T18:50:50.459+0000] {taskinstance.py:1159} INFO - Dependencies all met for dep_context=non-requeueable deps ti=<TaskInstance: weather_dag.transform_load_weather_data manual__2023-11-08T18:46:33.505188+00:00 [queued]>
[2023-11-08T18:50:50.467+0000] {taskinstance.py:1159} INFO - Dependencies all met for dep_context=requeueable deps ti=<TaskInstance: weather_dag.transform_load_weather_data manual__2023-11-08T18:46:33.505188+00:00 [queued]>
[2023-11-08T18:50:50.467+0000] {taskinstance.py:1361} INFO - Starting attempt 3 of 3
[2023-11-08T18:50:50.488+0000] {taskinstance.py:1382} INFO - Executing <Task(PythonOperator): transform_load_weather_data> on 2023-11-08 18:46:33.505188+00:00
[2023-11-08T18:50:50.495+0000] {standard_task_runner.py:57} INFO - Started process 25604 to run task
[2023-11-08T18:50:50.499+0000] {standard_task_runner.py:84} INFO - Running: ['airflow', 'tasks', 'run', 'weather_dag', 'transform_load_weather_data', 'manual__2023-11-08T18:46:33.505188+00:00', '--job-id', '51', '--raw', '--subdir', 'DAGS_FOLDER/weather_dags.py', '--cfg-path', '/tmp/tmpuklu4rhf']
[2023-11-08T18:50:50.500+0000] {standard_task_runner.py:85} INFO - Job 51: Subtask transform_load_weather_data
[2023-11-08T18:50:50.537+0000] {task_command.py:416} INFO - Running <TaskInstance: weather_dag.transform_load_weather_data manual__2023-11-08T18:46:33.505188+00:00 [running]> on host ip-172-31-22-131.eu-north-1.compute.internal
[2023-11-08T18:50:50.599+0000] {taskinstance.py:1662} INFO - Exporting env vars: AIRFLOW_CTX_DAG_OWNER='airflow' AIRFLOW_CTX_DAG_ID='weather_dag' AIRFLOW_CTX_TASK_ID='transform_load_weather_data' AIRFLOW_CTX_EXECUTION_DATE='2023-11-08T18:46:33.505188+00:00' AIRFLOW_CTX_TRY_NUMBER='3' AIRFLOW_CTX_DAG_RUN_ID='manual__2023-11-08T18:46:33.505188+00:00'
[2023-11-08T18:50:50.612+0000] {taskinstance.py:1937} ERROR - Task failed with exception
Traceback (most recent call last):
  File "/usr/local/lib/python3.10/dist-packages/airflow/operators/python.py", line 192, in execute
    return_value = self.execute_callable()
  File "/usr/local/lib/python3.10/dist-packages/airflow/operators/python.py", line 209, in execute_callable
    return self.python_callable(*self.op_args, **self.op_kwargs)
  File "/home/ubuntu/airflow/dags/weather_dags.py", line 54, in transform_load_data
    df_data.to.csv(f"{dt_string}.csv",index= False)
  File "/usr/local/lib/python3.10/dist-packages/pandas/core/generic.py", line 6204, in __getattr__
    return object.__getattribute__(self, name)
AttributeError: 'DataFrame' object has no attribute 'to'
[2023-11-08T18:50:50.621+0000] {taskinstance.py:1400} INFO - Marking task as FAILED. dag_id=weather_dag, task_id=transform_load_weather_data, execution_date=20231108T184633, start_date=20231108T185050, end_date=20231108T185050
[2023-11-08T18:50:50.634+0000] {standard_task_runner.py:104} ERROR - Failed to execute job 51 for task transform_load_weather_data ('DataFrame' object has no attribute 'to'; 25604)
[2023-11-08T18:50:50.672+0000] {local_task_job_runner.py:228} INFO - Task exited with return code 1
[2023-11-08T18:50:50.687+0000] {taskinstance.py:2778} INFO - 0 downstream tasks scheduled from follow-on schedule check
