[2023-11-08T18:48:31.082+0000] {taskinstance.py:1159} INFO - Dependencies all met for dep_context=non-requeueable deps ti=<TaskInstance: weather_dag.transform_load_weather_data manual__2023-11-08T18:48:20.341871+00:00 [queued]>
[2023-11-08T18:48:31.093+0000] {taskinstance.py:1159} INFO - Dependencies all met for dep_context=requeueable deps ti=<TaskInstance: weather_dag.transform_load_weather_data manual__2023-11-08T18:48:20.341871+00:00 [queued]>
[2023-11-08T18:48:31.093+0000] {taskinstance.py:1361} INFO - Starting attempt 1 of 3
[2023-11-08T18:48:31.120+0000] {taskinstance.py:1382} INFO - Executing <Task(PythonOperator): transform_load_weather_data> on 2023-11-08 18:48:20.341871+00:00
[2023-11-08T18:48:31.127+0000] {standard_task_runner.py:57} INFO - Started process 25465 to run task
[2023-11-08T18:48:31.133+0000] {standard_task_runner.py:84} INFO - Running: ['airflow', 'tasks', 'run', 'weather_dag', 'transform_load_weather_data', 'manual__2023-11-08T18:48:20.341871+00:00', '--job-id', '42', '--raw', '--subdir', 'DAGS_FOLDER/weather_dags.py', '--cfg-path', '/tmp/tmp1hpsu9ny']
[2023-11-08T18:48:31.134+0000] {standard_task_runner.py:85} INFO - Job 42: Subtask transform_load_weather_data
[2023-11-08T18:48:31.193+0000] {task_command.py:416} INFO - Running <TaskInstance: weather_dag.transform_load_weather_data manual__2023-11-08T18:48:20.341871+00:00 [running]> on host ip-172-31-22-131.eu-north-1.compute.internal
[2023-11-08T18:48:31.287+0000] {taskinstance.py:1662} INFO - Exporting env vars: AIRFLOW_CTX_DAG_OWNER='airflow' AIRFLOW_CTX_DAG_ID='weather_dag' AIRFLOW_CTX_TASK_ID='transform_load_weather_data' AIRFLOW_CTX_EXECUTION_DATE='2023-11-08T18:48:20.341871+00:00' AIRFLOW_CTX_TRY_NUMBER='1' AIRFLOW_CTX_DAG_RUN_ID='manual__2023-11-08T18:48:20.341871+00:00'
[2023-11-08T18:48:31.313+0000] {taskinstance.py:1937} ERROR - Task failed with exception
Traceback (most recent call last):
  File "/usr/local/lib/python3.10/dist-packages/airflow/operators/python.py", line 192, in execute
    return_value = self.execute_callable()
  File "/usr/local/lib/python3.10/dist-packages/airflow/operators/python.py", line 209, in execute_callable
    return self.python_callable(*self.op_args, **self.op_kwargs)
  File "/home/ubuntu/airflow/dags/weather_dags.py", line 51, in transform_load_data
    now = datatime.now()
NameError: name 'datatime' is not defined
[2023-11-08T18:48:31.319+0000] {taskinstance.py:1400} INFO - Marking task as UP_FOR_RETRY. dag_id=weather_dag, task_id=transform_load_weather_data, execution_date=20231108T184820, start_date=20231108T184831, end_date=20231108T184831
[2023-11-08T18:48:31.334+0000] {standard_task_runner.py:104} ERROR - Failed to execute job 42 for task transform_load_weather_data (name 'datatime' is not defined; 25465)
[2023-11-08T18:48:31.347+0000] {local_task_job_runner.py:228} INFO - Task exited with return code 1
[2023-11-08T18:48:31.372+0000] {taskinstance.py:2778} INFO - 0 downstream tasks scheduled from follow-on schedule check
