[2023-11-08T19:03:52.255+0000] {taskinstance.py:1159} INFO - Dependencies all met for dep_context=non-requeueable deps ti=<TaskInstance: weather_dag.transform_load_weather_data manual__2023-11-08T19:01:35.293150+00:00 [queued]>
[2023-11-08T19:03:52.260+0000] {taskinstance.py:1159} INFO - Dependencies all met for dep_context=requeueable deps ti=<TaskInstance: weather_dag.transform_load_weather_data manual__2023-11-08T19:01:35.293150+00:00 [queued]>
[2023-11-08T19:03:52.261+0000] {taskinstance.py:1361} INFO - Starting attempt 2 of 3
[2023-11-08T19:03:52.276+0000] {taskinstance.py:1382} INFO - Executing <Task(PythonOperator): transform_load_weather_data> on 2023-11-08 19:01:35.293150+00:00
[2023-11-08T19:03:52.280+0000] {standard_task_runner.py:57} INFO - Started process 26372 to run task
[2023-11-08T19:03:52.285+0000] {standard_task_runner.py:84} INFO - Running: ['airflow', 'tasks', 'run', 'weather_dag', 'transform_load_weather_data', 'manual__2023-11-08T19:01:35.293150+00:00', '--job-id', '61', '--raw', '--subdir', 'DAGS_FOLDER/weather_dags.py', '--cfg-path', '/tmp/tmpxg_2j632']
[2023-11-08T19:03:52.285+0000] {standard_task_runner.py:85} INFO - Job 61: Subtask transform_load_weather_data
[2023-11-08T19:03:52.322+0000] {task_command.py:416} INFO - Running <TaskInstance: weather_dag.transform_load_weather_data manual__2023-11-08T19:01:35.293150+00:00 [running]> on host ip-172-31-22-131.eu-north-1.compute.internal
[2023-11-08T19:03:52.388+0000] {taskinstance.py:1662} INFO - Exporting env vars: AIRFLOW_CTX_DAG_OWNER='airflow' AIRFLOW_CTX_DAG_ID='weather_dag' AIRFLOW_CTX_TASK_ID='transform_load_weather_data' AIRFLOW_CTX_EXECUTION_DATE='2023-11-08T19:01:35.293150+00:00' AIRFLOW_CTX_TRY_NUMBER='2' AIRFLOW_CTX_DAG_RUN_ID='manual__2023-11-08T19:01:35.293150+00:00'
[2023-11-08T19:03:52.841+0000] {credentials.py:549} INFO - Found credentials from IAM Role: S3-full-access
[2023-11-08T19:03:54.091+0000] {taskinstance.py:1937} ERROR - Task failed with exception
Traceback (most recent call last):
  File "/usr/local/lib/python3.10/dist-packages/s3fs/core.py", line 113, in _error_wrapper
    return await func(*args, **kwargs)
  File "/usr/local/lib/python3.10/dist-packages/aiobotocore/client.py", line 383, in _make_api_call
    raise error_class(parsed_response, operation_name)
botocore.exceptions.ClientError: An error occurred (AccessDenied) when calling the PutObject operation: No AWSAccessKey was presented.

The above exception was the direct cause of the following exception:

Traceback (most recent call last):
  File "/usr/local/lib/python3.10/dist-packages/airflow/operators/python.py", line 192, in execute
    return_value = self.execute_callable()
  File "/usr/local/lib/python3.10/dist-packages/airflow/operators/python.py", line 209, in execute_callable
    return self.python_callable(*self.op_args, **self.op_kwargs)
  File "/home/ubuntu/airflow/dags/weather_dags.py", line 54, in transform_load_data
    df_data.to_csv(f"s3://weatherapibucket-at/{dt_string}.csv",index= False)
  File "/usr/local/lib/python3.10/dist-packages/pandas/core/generic.py", line 3902, in to_csv
    return DataFrameRenderer(formatter).to_csv(
  File "/usr/local/lib/python3.10/dist-packages/pandas/io/formats/format.py", line 1152, in to_csv
    csv_formatter.save()
  File "/usr/local/lib/python3.10/dist-packages/pandas/io/formats/csvs.py", line 247, in save
    with get_handle(
  File "/usr/local/lib/python3.10/dist-packages/pandas/io/common.py", line 142, in __exit__
    self.close()
  File "/usr/local/lib/python3.10/dist-packages/pandas/io/common.py", line 134, in close
    handle.close()
  File "/usr/local/lib/python3.10/dist-packages/fsspec/spec.py", line 1942, in close
    self.flush(force=True)
  File "/usr/local/lib/python3.10/dist-packages/fsspec/spec.py", line 1813, in flush
    if self._upload_chunk(final=force) is not False:
  File "/usr/local/lib/python3.10/dist-packages/s3fs/core.py", line 2288, in _upload_chunk
    self.commit()
  File "/usr/local/lib/python3.10/dist-packages/s3fs/core.py", line 2306, in commit
    write_result = self._call_s3("put_object", **kw)
  File "/usr/local/lib/python3.10/dist-packages/s3fs/core.py", line 2151, in _call_s3
    return self.fs.call_s3(method, self.s3_additional_kwargs, *kwarglist, **kwargs)
  File "/usr/local/lib/python3.10/dist-packages/fsspec/asyn.py", line 118, in wrapper
    return sync(self.loop, func, *args, **kwargs)
  File "/usr/local/lib/python3.10/dist-packages/fsspec/asyn.py", line 103, in sync
    raise return_result
  File "/usr/local/lib/python3.10/dist-packages/fsspec/asyn.py", line 56, in _runner
    result[0] = await coro
  File "/usr/local/lib/python3.10/dist-packages/s3fs/core.py", line 348, in _call_s3
    return await _error_wrapper(
  File "/usr/local/lib/python3.10/dist-packages/s3fs/core.py", line 140, in _error_wrapper
    raise err
PermissionError: No AWSAccessKey was presented.
[2023-11-08T19:03:54.112+0000] {taskinstance.py:1400} INFO - Marking task as UP_FOR_RETRY. dag_id=weather_dag, task_id=transform_load_weather_data, execution_date=20231108T190135, start_date=20231108T190352, end_date=20231108T190354
[2023-11-08T19:03:54.127+0000] {standard_task_runner.py:104} ERROR - Failed to execute job 61 for task transform_load_weather_data (No AWSAccessKey was presented.; 26372)
[2023-11-08T19:03:54.144+0000] {local_task_job_runner.py:228} INFO - Task exited with return code 1
[2023-11-08T19:03:54.159+0000] {taskinstance.py:2778} INFO - 0 downstream tasks scheduled from follow-on schedule check
